2022-04-20 17:02:37,547 INFO    MainThread:139338 [internal.py:wandb_internal():92] W&B internal server running at pid: 139338, started at: 2022-04-20 17:02:37.547384
2022-04-20 17:02:37,551 INFO    WriterThread:139338 [datastore.py:open_for_write():77] open: /home/ubuntu/environment/tutorial/wandb/run-20220420_170237-1ezhjtdn/run-1ezhjtdn.wandb
2022-04-20 17:02:37,552 DEBUG   SenderThread:139338 [sender.py:send():235] send: header
2022-04-20 17:02:37,552 DEBUG   SenderThread:139338 [sender.py:send():235] send: run
2022-04-20 17:02:37,693 ERROR   SenderThread:139338 [internal_api.py:execute():144] 401 response executing GraphQL.
2022-04-20 17:02:37,694 ERROR   SenderThread:139338 [internal_api.py:execute():145] {"errors":[{"message":"permission denied","path":["upsertBucket"],"extensions":{"code":"PERMISSION_ERROR"}}],"data":{"upsertBucket":null}}
2022-04-20 17:02:38,551 INFO    WriterThread:139338 [datastore.py:close():281] close: /home/ubuntu/environment/tutorial/wandb/run-20220420_170237-1ezhjtdn/run-1ezhjtdn.wandb
2022-04-20 17:02:38,552 INFO    HandlerThread:139338 [handler.py:finish():790] shutting down handler
2022-04-20 17:02:38,552 ERROR   MainThread:139338 [internal.py:wandb_internal():167] Thread SenderThread:
Traceback (most recent call last):
  File "/home/ubuntu/.local/lib/python3.8/site-packages/wandb/sdk/lib/retry.py", line 102, in __call__
    result = self._call_fn(*args, **kwargs)
  File "/home/ubuntu/.local/lib/python3.8/site-packages/wandb/sdk/internal/internal_api.py", line 147, in execute
    six.reraise(*sys.exc_info())
  File "/usr/lib/python3/dist-packages/six.py", line 703, in reraise
    raise value
  File "/home/ubuntu/.local/lib/python3.8/site-packages/wandb/sdk/internal/internal_api.py", line 141, in execute
    return self.client.execute(*args, **kwargs)
  File "/home/ubuntu/.local/lib/python3.8/site-packages/wandb/vendor/gql-0.2.0/wandb_gql/client.py", line 52, in execute
    result = self._get_result(document, *args, **kwargs)
  File "/home/ubuntu/.local/lib/python3.8/site-packages/wandb/vendor/gql-0.2.0/wandb_gql/client.py", line 60, in _get_result
    return self.transport.execute(document, *args, **kwargs)
  File "/home/ubuntu/.local/lib/python3.8/site-packages/wandb/vendor/gql-0.2.0/wandb_gql/transport/requests.py", line 39, in execute
    request.raise_for_status()
  File "/usr/lib/python3/dist-packages/requests/models.py", line 940, in raise_for_status
    raise HTTPError(http_error_msg, response=self)
requests.exceptions.HTTPError: 401 Client Error: Unauthorized for url: https://api.wandb.ai/graphql

During handling of the above exception, another exception occurred:

Traceback (most recent call last):
  File "/home/ubuntu/.local/lib/python3.8/site-packages/wandb/apis/normalize.py", line 24, in wrapper
    return func(*args, **kwargs)
  File "/home/ubuntu/.local/lib/python3.8/site-packages/wandb/sdk/internal/internal_api.py", line 1315, in upsert_run
    response = self.gql(mutation, variable_values=variable_values, **kwargs)
  File "/home/ubuntu/.local/lib/python3.8/site-packages/wandb/sdk/lib/retry.py", line 118, in __call__
    if not check_retry_fn(e):
  File "/home/ubuntu/.local/lib/python3.8/site-packages/wandb/util.py", line 869, in no_retry_auth
    raise CommError("Invalid or missing api_key. Run `wandb login`")
wandb.errors.CommError: Invalid or missing api_key. Run `wandb login`

During handling of the above exception, another exception occurred:

Traceback (most recent call last):
  File "/home/ubuntu/.local/lib/python3.8/site-packages/wandb/sdk/internal/internal_util.py", line 54, in run
    self._run()
  File "/home/ubuntu/.local/lib/python3.8/site-packages/wandb/sdk/internal/internal_util.py", line 105, in _run
    self._process(record)
  File "/home/ubuntu/.local/lib/python3.8/site-packages/wandb/sdk/internal/internal.py", line 312, in _process
    self._sm.send(record)
  File "/home/ubuntu/.local/lib/python3.8/site-packages/wandb/sdk/internal/sender.py", line 237, in send
    send_handler(record)
  File "/home/ubuntu/.local/lib/python3.8/site-packages/wandb/sdk/internal/sender.py", line 695, in send_run
    self._init_run(run, config_value_dict)
  File "/home/ubuntu/.local/lib/python3.8/site-packages/wandb/sdk/internal/sender.py", line 719, in _init_run
    server_run, inserted = self._api.upsert_run(
  File "/home/ubuntu/.local/lib/python3.8/site-packages/wandb/apis/normalize.py", line 62, in wrapper
    six.reraise(CommError, CommError(message, err), sys.exc_info()[2])
  File "/usr/lib/python3/dist-packages/six.py", line 702, in reraise
    raise value.with_traceback(tb)
  File "/home/ubuntu/.local/lib/python3.8/site-packages/wandb/apis/normalize.py", line 24, in wrapper
    return func(*args, **kwargs)
  File "/home/ubuntu/.local/lib/python3.8/site-packages/wandb/sdk/internal/internal_api.py", line 1315, in upsert_run
    response = self.gql(mutation, variable_values=variable_values, **kwargs)
  File "/home/ubuntu/.local/lib/python3.8/site-packages/wandb/sdk/lib/retry.py", line 118, in __call__
    if not check_retry_fn(e):
  File "/home/ubuntu/.local/lib/python3.8/site-packages/wandb/util.py", line 869, in no_retry_auth
    raise CommError("Invalid or missing api_key. Run `wandb login`")
wandb.errors.CommError: Invalid or missing api_key. Run `wandb login`
2022-04-20 17:02:40,571 INFO    MainThread:139338 [internal.py:handle_exit():82] Internal process exited
